Workbook

Sheet El Retiro
A1: EMPRESA | B1: PPU | C1: INTERNO | D1: TIPO BUS | E1: TIPO FLOTA | F1: MARCA CHASIS | G1: TERMINAL OP | H1: Inicio Operación | K1: Cargo | L1: Nombre
A2: US1 | B2: SHCY11 | C2: 1002 | D2: A2 | E2: FOB | F2: VOLVO | G2: EL RETIRO | H2: 44912 | K2: Jefe de Terminal | L2: Jose Lagunas
A3: US1 | B3: SHCY32 | C3: 1003 | D3: A2 | E3: FOB | F3: VOLVO | G3: EL RETIRO | H3: 44912 | K3: Supervisor de Flota | L3: Giovanni Nicoletti
A4: US1 | B4: SHCY33 | C4: 1004 | D4: A2 | E4: FOB | F4: VOLVO | G4: EL RETIRO | H4: 44912 | K4: Supervisor de Flota | L4: John Santibáñez
A5: US1 | B5: SHCY34 | C5: 1005 | D5: A2 | E5: FOB | F5: VOLVO | G5: EL RETIRO | H5: 44912
A6: US1 | B6: SHCY39 | C6: 1008 | D6: A2 | E6: FR | F6: VOLVO | G6: EL RETIRO | H6: 44912
A7: US1 | B7: SHCY40 | C7: 1009 | D7: A2 | E7: FR | F7: VOLVO | G7: EL RETIRO | H7: 44912
A8: US1 | B8: SHCY46 | C8: 1010 | D8: A2 | E8: FOB | F8: VOLVO | G8: EL RETIRO | H8: 44912
A9: US1 | B9: SHCY47 | C9: 1011 | D9: A2 | E9: FOB | F9: VOLVO | G9: EL RETIRO | H9: 44912 | K9: Bus | L9: Cuenta de MARCA CHASIS
A10: US1 | B10: SHCY49 | C10: 1012 | D10: A2 | E10: FOB | F10: VOLVO | G10: EL RETIRO | H10: 44912 | K10: A2 | L10: 11
A11: US1 | B11: SHCY50 | C11: 1013 | D11: A2 | E11: FOB | F11: VOLVO | G11: EL RETIRO | H11: 44912 | K11: VOLVO | L11: 11
A12: US1 | B12: SHCY55 | C12: 1015 | D12: A2 | E12: FOB | F12: VOLVO | G12: EL RETIRO | H12: 44912 | K12: B2 | L12: 28
A13: US1 | B13: LXDH97 | C13: 2055 | D13: B2 | E13: FOB | F13: SCANIA | G13: EL RETIRO | H13: 44912 | K13: SCANIA | L13: 28
A14: US1 | B14: LXDJ16 | C14: 2064 | D14: B2 | E14: FOB | F14: SCANIA | G14: EL RETIRO | H14: 44933 | K14: C2 | L14: 19
A15: US1 | B15: LXDJ22 | C15: 2070 | D15: B2 | E15: FOB | F15: SCANIA | G15: EL RETIRO | H15: 44912 | K15: VOLVO | L15: 19
A16: US1 | B16: SHXF30 | C16: 4035 | D16: C2 | E16: FOB | F16: VOLVO | G16: EL RETIRO | H16: 44928 | K16: Total general | L16: 58
A17: US1 | B17: SHXG17 | C17: 4036 | D17: C2 | E17: FOB | F17: VOLVO | G17: EL RETIRO | H17: 44928
A18: US1 | B18: SHXG31 | C18: 4038 | D18: C2 | E18: FOB | F18: VOLVO | G18: EL RETIRO | H18: 44928
A19: US1 | B19: SHXG34 | C19: 4040 | D19: C2 | E19: FOB | F19: VOLVO | G19: EL RETIRO | H19: 44928 | K19: BUS QUEMADO
A20: US1 | B20: SJPC36 | C20: 4043 | D20: C2 | E20: FR | F20: VOLVO | G20: EL RETIRO | H20: 44928 | K20: LXDJ23 | L20: 45859
A21: US1 | B21: SJPC37 | C21: 4044 | D21: C2 | E21: FOB | F21: VOLVO | G21: EL RETIRO | H21: 44928
A22: US1 | B22: SJPC41 | C22: 4046 | D22: C2 | E22: FOB | F22: VOLVO | G22: EL RETIRO | H22: 44928
A23: US1 | B23: SJPC45 | C23: 4048 | D23: C2 | E23: FOB | F23: VOLVO | G23: EL RETIRO | H23: 44928
A24: US1 | B24: SJPC48 | C24: 4049 | D24: C2 | E24: FOB | F24: VOLVO | G24: EL RETIRO | H24: 44928
A25: US1 | B25: SJPC49 | C25: 4050 | D25: C2 | E25: FOB | F25: VOLVO | G25: EL RETIRO | H25: 44928
A26: US1 | B26: SJPC52 | C26: 4052 | D26: C2 | E26: FOB | F26: VOLVO | G26: EL RETIRO | H26: 44928
A27: US1 | B27: SJPD89 | C27: 4057 | D27: C2 | E27: FOB | F27: VOLVO | G27: EL RETIRO | H27: 44928
A28: US1 | B28: SJPD90 | C28: 4058 | D28: C2 | E28: FOB | F28: VOLVO | G28: EL RETIRO | H28: 44928
A29: US1 | B29: SJPD91 | C29: 4059 | D29: C2 | E29: FOB | F29: VOLVO | G29: EL RETIRO | H29: 44928
A30: US1 | B30: SJPD93 | C30: 4061 | D30: C2 | E30: FOB | F30: VOLVO | G30: EL RETIRO | H30: 44928
A31: US1 | B31: SJPD95 | C31: 4063 | D31: C2 | E31: FOB | F31: VOLVO | G31: EL RETIRO | H31: 44928
A32: US1 | B32: SJPD96 | C32: 4064 | D32: C2 | E32: FOB | F32: VOLVO | G32: EL RETIRO | H32: 44928
... A59: US1 | B59: LXDJ20 | C59: 2068 | D59: B2 | E59: FOB | F59: SCANIA | G59: EL RETIRO | H59: 44928

Sheet Sta. Margarita
A1: EMPRESA | B1: PLACA | C1: INTERNO | D1: TIPO BUS | E1: TIPO FLOTA | F1: MARCA CHASIS | G1: TERMINAL OP | H1: Inicio Operación | K1: Cargo | L1: Nombre
A2: US1 | B2: LXDH88 | C2: 2046 | D2: B2 | E2: FOB | F2: SCANIA | G2: SANTA MARGARITA | H2: 44912 | K2: Jefe de Terminal | L2: Jose Lagunas
A3: US1 | B3: LXDJ28 | C3: 2076 | D3: B2 | E3: FOB | F3: SCANIA | G3: SANTA MARGARITA | H3: 44928 | K3: Supervisor de Flota | L3: Giovanni Nicoletti
A4: US1 | B4: LXDJ30 | C4: 2078 | D4: B2 | E4: FOB | F4: SCANIA | G4: SANTA MARGARITA | H4: 44928 | K4: Supervisor de Flota | L4: John Santibáñez
A5: US1 | B5: LXDJ17 | C5: 2065 | D5: B2 | E5: FOB | F5: SCANIA | G5: SANTA MARGARITA | H5: 44933
A6: US1 | B6: LXDJ18 | C6: 2066 | D6: B2 | E6: FOB | F6: SCANIA | G6: SANTA MARGARITA | H6: 44928
A7: US1 | B7: LXDJ26 | C7: 2074 | D7: B2 | E7: FOB | F7: SCANIA | G7: SANTA MARGARITA | H7: 44933
A8: US1 | B8: LXDJ27 | C8: 2075 | D8: B2 | E8: FOB | F8: SCANIA | G8: SANTA MARGARITA | H8: 44933 | K8: BUS | L8: CANTIDAD
A9: US1 | B9: LXDJ29 | C9: 2077 | D9: B2 | E9: FOB | F9: SCANIA | G9: SANTA MARGARITA | H9: 44933 | K9: B2 | L9: 9
A10: US1 | B10: LXDJ31 | C10: 2079 | D10: B2 | E10: FOB | F10: SCANIA | G10: SANTA MARGARITA | H10: 44928 | K10: SCANIA | L10: 9
A11: US1 | B11: SHCY17 | C11: 4027 | D11: C2 | E11: FOB | F11: VOLVO | G11: SANTA MARGARITA | H11: 44928 | K11: C2 | L11: 19
A12: US1 | B12: SHCY18 | C12: 4025 | D12: C2 | E12: FOB | F12: VOLVO | G12: SANTA MARGARITA | H12: 44928 | K12: VOLVO | L12: 19
A13: US1 | B13: SHXC20 | C13: 4026 | D13: C2 | E13: FOB | F13: VOLVO | G13: SANTA MARGARITA | H13: 44928 | K13: Total general | L13: 28
A14: US1 | B14: SHXD76 | C14: 4028 | D14: C2 | E14: FOB | F14: VOLVO | G14: SANTA MARGARITA | H14: 44928
A15: US1 | B15: SHXD78 | C15: 4029 | D15: C2 | E15: FOB | F15: VOLVO | G15: SANTA MARGARITA | H15: 44928
A16: US1 | B16: SHXF26 | C16: 4032 | D16: C2 | E16: FOB | F16: VOLVO | G16: SANTA MARGARITA | H16: 44928
A17: US1 | B17: SHXF27 | C17: 4033 | D17: C2 | E17: FOB | F17: VOLVO | G17: SANTA MARGARITA | H17: 44928
A18: US1 | B18: SHXF28 | C18: 4034 | D18: C2 | E18: FOB | F18: VOLVO | G18: SANTA MARGARITA | H18: 44928
A19: US1 | B19: SHXG32 | C19: 4039 | D19: C2 | E19: FOB | F19: VOLVO | G19: SANTA MARGARITA | H19: 44928
A20: US1 | B20: SJPC38 | C20: 4045 | D20: C2 | E20: FOB | F20: VOLVO | G20: SANTA MARGARITA | H20: 44928
A21: US1 | B21: SHXF24 | C21: 4030 | D21: C2 | E21: FOB | F21: VOLVO | G21: SANTA MARGARITA | H21: 44928
A22: US1 | B22: SHXG30 | C22: 4037 | D22: C2 | E22: FOB | F22: VOLVO | G22: SANTA MARGARITA | H22: 44928
A23: US1 | B23: SJPC44 | C23: 4047 | D23: C2 | E23: FOB | F23: VOLVO | G23: SANTA MARGARITA | H23: 44928
A24: US1 | B24: SJPC56 | C24: 4053 | D24: C2 | E24: FOB | F24: VOLVO | G24: SANTA MARGARITA | H24: 44928
A25: US1 | B25: SJPC66 | C25: 4054 | D25: C2 | E25: FOB | F25: VOLVO | G25: SANTA MARGARITA | H25: 44928
... A29: US1 | B29: SJPD99 | C29: 4065 | D29: C2 | E29: FOB | F29: VOLVO | G29: SANTA MARGARITA | H29: 44928

Sheet Coca-Cola
A1: EMPRESA | B1: PLACA | C1: INTERNO | D1: TIPO BUS | E1: TIPO FLOTA | F1: MARCA CHASIS | G1: TERMINAL OP | H1: Inicio Operación | K1: Cargo | L1: Nombre | M1: Teléfono
K2: Subgerente Flota | L2: Fabián Contreras | M2: 9 82461903
K3: Jefe de Terminal | L3: Gustavo Rojas | M3: 9 32007087
K4: Jefe Taller | L4: Roberto Padilla | M4: 9 45814567
K7: BUS | L7: CANTIDAD
K8: (en blanco)
K9: (en blanco)
K10: Total general

Sheet Condell
A1: EMPRESA | B1: PLACA | C1: INTERNO | D1: TIPO BUS | E1: TIPO FLOTA | F1: MARCA CHASIS | G1: TERMINAL OP | H1: Inicio Operación | J1: Cargo | K1: Nombre
A2: US1 | B2: SHCX53 | C2: 1000 | D2: A2 | E2: FOB | F2: VOLVO | G2: CONDELL | H2: 44912 | J2: Jefe de Terminal | K2: Boris Caceres
A3: US1 | B3: SHCY10 | C3: 1001 | D3: A2 | E3: FOB | F3: VOLVO | G3: CONDELL | H3: 44912 | J3: Supervisor de Flota | K3: Francisco Fayos
A4: US1 | B4: SHXF83 | C4: 1018 | D4: A2 | E4: FOB | F4: VOLVO | G4: CONDELL | H4: 44933 | J4: Supervisor de Flota | K4: Jorge Villagra
A5: US1 | B5: SHXG99 | C5: 1019 | D5: A2 | E5: FOB | F5: VOLVO | G5: CONDELL | H5: 44933 | J5: Supervisor de Flota | K5: Juan Martini
A6: US1 | B6: SHCY62 | C6: 1020 | D6: A2 | E6: FOB | F6: VOLVO | G6: CONDELL | H6: 44933
A7: US1 | B7: SHCY45 | C7: 1021 | D7: A2 | E7: FOB | F7: VOLVO | G7: CONDELL | H7: 44933
A8: US1 | B8: SHCY44 | C8: 1022 | D8: A2 | E8: FOB | F8: VOLVO | G8: CONDELL | H8: 44933 | J8: BUS | K8: CANTIDAD
A9: US1 | B9: SHCY43 | C9: 1023 | D9: A2 | E9: FR | F9: VOLVO | G9: CONDELL | H9: 44933 | J9: A2 | K9: 10
A10: US1 | B10: SHXD83 | C10: 1028 | D10: A2 | E10: FOB | F10: VOLVO | G10: CONDELL | H10: 44933 | J10: VOLVO | K10: 10
A11: US1 | B11: SHCY38 | C11: 1029 | D11: A2 | E11: FOB | F11: VOLVO | G11: CONDELL | H11: 44933 | J11: B2 | K11: 12
A12: US1 | B12: LDJP73 | C12: 2084 | D12: B2 | E12: FOB | F12: MERCEDES BENZ | G12: CONDELL | H12: 44933 | J12: MERCEDES BENZ | K12: 12
A13: US1 | B13: LDJV43 | C13: 2085 | D13: B2 | E13: FOB | F13: MERCEDES BENZ | G13: CONDELL | H13: 44933 | J13: BE | K13: 75
A14: US1 | B14: LDJV46 | C14: 2088 | D14: B2 | E14: FOB | F14: MERCEDES BENZ | G14: CONDELL | H14: 44933 | J14: FOTON | K14: 75
A15: US1 | B15: LDJV48 | C15: 2089 | D15: B2 | E15: FOB | F15: MERCEDES BENZ | G15: CONDELL | H15: 44933 | J15: C2 | K15: 31
A16: US1 | B16: LDJV49 | C16: 2090 | D16: B2 | E16: FOB | F16: MERCEDES BENZ | G16: CONDELL | H16: 44933 | J16: MERCEDES BENZ | K16: 24
A17: US1 | B17: LDJV51 | C17: 2092 | D17: B2 | E17: FOB | F17: MERCEDES BENZ | G17: CONDELL | H17: 44933 | J17: VOLVO | K17: 7
A18: US1 | B18: LDJV52 | C18: 2093 | D18: B2 | E18: FOB | F18: MERCEDES BENZ | G18: CONDELL | H18: 44933 | J18: Total general | K18: 128
A19: US1 | B19: LDJW29 | C19: 2094 | D19: B2 | E19: FOB | F19: MERCEDES BENZ | G19: CONDELL | H19: 44933
A20: US1 | B20: LDJW48 | C20: 2111 | D20: B2 | E20: FOB | F20: MERCEDES BENZ | G20: CONDELL | H20: 44933 | J20: BUS QUEMADO
A21: US1 | B21: SJTD55 | C21: 3000 | D21: BE | E21: FR | F21: FOTON | G21: CONDELL | H21: 44933 | J21: SJTD58 | K21: 45743
A22: US1 | B22: SJTD56 | C22: 3001 | D22: BE | E22: FR | F22: FOTON | G22: CONDELL | H22: 44933
A23: US1 | B23: SJTD57 | C23: 3002 | D23: BE | E23: FR | F23: FOTON | G23: CONDELL | H23: 44933
A24: US1 | B24: SJTD61 | C24: 3004 | D24: BE | E24: FR | F24: FOTON | G24: CONDELL | H24: 44933
A25: US1 | B25: SJTD62 | C25: 3005 | D25: BE | E25: FR | F25: FOTON | G25: CONDELL | H25: 44933
A26: US1 | B26: SJTD63 | C26: 3006 | D26: BE | E26: FR | F26: FOTON | G26: CONDELL | H26: 44933
A27: US1 | B27: SJTD64 | C27: 3007 | D27: BE | E27: FR | F27: FOTON | G27: CONDELL | H27: 44933
A28: US1 | B28: SJTD65 | C28: 3008 | D28: BE | E28: FR | F28: FOTON | G28: CONDELL | H28: 44933
A29: US1 | B29: SJTD66 | C29: 3009 | D29: BE | E29: FR | F29: FOTON | G29: CONDELL | H29: 44933
A30: US1 | B30: SKHF49 | C30: 3010 | D30: BE | E30: FOB | F30: FOTON | G30: CONDELL | H30: 44933
A31: US1 | B31: SKHF84 | C31: 3011 | D31: BE | E31: FOB | F31: FOTON | G31: CONDELL | H31: 44933
A32: US1 | B32: SKHF87 | C32: 3012 | D32: BE | E32: FOB | F32: FOTON | G32: CONDELL | H32: 44933
A33: US1 | B33: SKHF91 | C33: 3013 | D33: BE | E33: FOB | F33: FOTON | G33: CONDELL | H33: 44933
... A129: US1 | B129: TXZK38 | C129: 3140 | D129: BE | E129: FR | F129: FOTON | G129: CONDELL | H129: 45702

Sheet Sta. Marta
A1: EMPRESA | B1: PLACA | C1: INTERNO | D1: TIPO BUS | E1: TIPO FLOTA | F1: MARCA CHASIS | G1: TERMINAL OP | H1: Inicio Operación | J1: Cargo | K1: Nombre
A2: US1 | B2: SHCY36 | C2: 1006 | D2: A2 | E2: FOB | F2: VOLVO | G2: STA MARTA | H2: 45038 | J2: Supervisor de Flota | K2: Margarita Tafall
A3: US1 | B3: SHCY37 | C3: 1007 | D3: A2 | E3: FOB | F3: VOLVO | G3: STA MARTA | H3: 45038 | J3: Supervisor de Flota | K3: Luis Vargas
A4: US1 | B4: SHCY51 | C4: 1014 | D4: A2 | E4: FOB | F4: VOLVO | G4: STA MARTA | H4: 45038 | J4: Supervisor de Flota | K4: Carlos Moya
A5: US1 | B5: SHCY16 | C5: 1016 | D5: A2 | E5: FOB | F5: VOLVO | G5: STA MARTA | H5: 45038 | J5: Supervisor de Flota | K5: Jose Vargas
A6: US1 | B6: SHCY35 | C6: 1017 | D6: A2 | E6: FOB | F6: VOLVO | G6: STA MARTA | H6: 45038 | J6: Supervisor de Flota | K6: Darochs Diaz
A7: US1 | B7: SHCX43 | C7: 1024 | D7: A2 | E7: FOB | F7: VOLVO | G7: STA MARTA | H7: 45038
A8: US1 | B8: SHCY59 | C8: 1025 | D8: A2 | E8: FOB | F8: VOLVO | G8: STA MARTA | H8: 45038
A9: US1 | B9: SHCX54 | C9: 1026 | D9: A2 | E9: FOB | F9: VOLVO | G9: STA MARTA | H9: 45038 | J9: BUS | K9: CANTIDAD
A10: US1 | B10: SHCY58 | C10: 1027 | D10: A2 | E10: FOB | F10: VOLVO | G10: STA MARTA | H10: 45038 | J10: A2 | K10: 16
A11: US1 | B11: SHXF23 | C11: 1030 | D11: A2 | E11: FOB | F11: VOLVO | G11: STA MARTA | H11: 45038 | J11: VOLVO | K11: 16
A12: US1 | B12: SHCY64 | C12: 1031 | D12: A2 | E12: FOB | F12: VOLVO | G12: STA MARTA | H12: 45038 | J12: B2 | K12: 22
A13: US1 | B13: SHCY57 | C13: 1032 | D13: A2 | E13: FOB | F13: VOLVO | G13: STA MARTA | H13: 45038 | J13: MERCEDES BENZ | K13: 22
A14: US1 | B14: SHXF45 | C14: 1033 | D14: A2 | E14: FOB | F14: VOLVO | G14: STA MARTA | H14: 45038 | J14: BPAL | K14: 43
A15: US1 | B15: SHXF19 | C15: 1034 | D15: A2 | E15: FOB | F15: VOLVO | G15: STA MARTA | H15: 45038 | J15: MERCEDES BENZ | K15: 40
A16: US1 | B16: SJPB20 | C16: 1035 | D16: A2 | E16: FOB | F16: VOLVO | G16: STA MARTA | H16: 45038 | J16: SCANIA | K16: 3
A17: US1 | B17: SJPC30 | C17: 1036 | D17: A2 | E17: FOB | F17: VOLVO | G17: STA MARTA | H17: 45038 | J17: BE | K17: 66
A18: US1 | B18: FLXS43 | C18: 2000 | D18: BPAL | E18: FOB | F18: MERCEDES BENZ | G18: STA MARTA | H18: 45038 | J18: FOTON | K18: 66
A19: US1 | B19: FLXS44 | C19: 2001 | D19: BPAL | E19: FOB | F19: MERCEDES BENZ | G19: STA MARTA | H19: 45038 | J19: Total general | K19: 147
A20: US1 | B20: FLXS45 | C20: 2002 | D20: BPAL | E20: FOB | F20: MERCEDES BENZ | G20: STA MARTA | H20: 45038
A21: US1 | B21: FLXS46 | C21: 2003 | D21: BPAL | E21: FOB | F21: MERCEDES BENZ | G21: STA MARTA | H21: 45038
A22: US1 | B22: FLXS47 | C22: 2004 | D22: BPAL | E22: FOB | F22: MERCEDES BENZ | G22: STA MARTA | H22: 45038
A23: US1 | B23: FLXS48 | C23: 2005 | D23: BPAL | E23: FOB | F23: MERCEDES BENZ | G23: STA MARTA | H23: 45038
A24: US1 | B24: FLXS49 | C24: 2006 | D24: BPAL | E24: FOB | F24: MERCEDES BENZ | G24: STA MARTA | H24: 45038
A25: US1 | B25: FLXS50 | C25: 2007 | D25: BPAL | E25: FOB | F25: MERCEDES BENZ | G25: STA MARTA | H25: 45038
A26: US1 | B26: FLXS51 | C26: 2008 | D26: BPAL | E26: FOB | F26: MERCEDES BENZ | G26: STA MARTA | H26: 45038
A27: US1 | B27: FLXS52 | C27: 2009 | D27: BPAL | E27: FOB | F27: MERCEDES BENZ | G27: STA MARTA | H27: 45038
A28: US1 | B28: FLXS53 | C28: 2010 | D28: BPAL | E28: FOB | F28: MERCEDES BENZ | G28: STA MARTA | H28: 45038
A29: US1 | B29: FLXS54 | C29: 2011 | D29: BPAL | E29: FOB | F29: MERCEDES BENZ | G29: STA MARTA | H29: 45038
A30: US1 | B30: FLXS55 | C30: 2012 | D30: BPAL | E30: FOB | F30: MERCEDES BENZ | G30: STA MARTA | H30: 45038
A31: US1 | B31: FLXS56 | C31: 2013 | D31: BPAL | E31: FOB | F31: MERCEDES BENZ | G31: STA MARTA | H31: 45038
... A148: US1 | B148: FLXP82 | C148: 2041 | D148: BPAL | E148: FS | F148: MERCEDES BENZ | G148: STA MARTA | H148: 45024

Sheet A. Luco
A1: EMPRESA | B1: PLACA | C1: INTERNO | D1: TIPO BUS | E1: TIPO FLOTA | F1: MARCA CHASIS | G1: TERMINAL OP | H1: Inicio Operación | J1: Cargo | K1: Nombre
A2: US2 | B2: SHCX61 | C2: 5001 | D2: A2 | E2: FOB | F2: VOLVO | G2: A. LUCO | H2: 44982 | J2: Supervisor de Flota | K2: Segundo Burgos
A3: US2 | B3: SHCX44 | C3: 5002 | D3: A2 | E3: FOB | F3: VOLVO | G3: A. LUCO | H3: 44982
A4: US2 | B4: SHCY41 | C4: 5003 | D4: A2 | E4: FOB | F4: VOLVO | G4: A. LUCO | H4: 44982 | J4: BUS | K4: CANTIDAD
A5: US2 | B5: SHCY56 | C5: 5004 | D5: A2 | E5: FOB | F5: VOLVO | G5: A. LUCO | H5: 44982 | J5: A2 | K5: 6
A6: US2 | B6: SHXF37 | C6: 5005 | D6: A2 | E6: FOB | F6: VOLVO | G6: A. LUCO | H6: 44982 | J6: VOLVO | K6: 6
A7: US2 | B7: TPWW72 | C7: 5023 | D7: A2 | E7: FOB | F7: VOLVO | G7: A. LUCO | H7: 45537 | J7: B2 | K7: 33
A8: US2 | B8: FLXR78 | C8: 6000 | D8: BPAL | E8: FOB | F8: MERCEDES BENZ | G8: A. LUCO | H8: 45003 | J8: VOLVO | K8: 33
A9: US2 | B9: FLXR79 | C9: 6001 | D9: BPAL | E9: FOB | F9: MERCEDES BENZ | G9: A. LUCO | H9: 45003 | J9: BPAL | K9: 24
A10: US2 | B10: FLXR80 | C10: 6002 | D10: BPAL | E10: FOB | F10: MERCEDES BENZ | G10: A. LUCO | H10: 45003 | J10: MERCEDES BENZ | K10: 24
A11: US2 | B11: FLXR81 | C11: 6003 | D11: BPAL | E11: FOB | F11: MERCEDES BENZ | G11: A. LUCO | H11: 45003 | J11: Total general | K11: 63
A12: US2 | B12: FLXR82 | C12: 6004 | D12: BPAL | E12: FOB | F12: MERCEDES BENZ | G12: A. LUCO | H12: 45003
A13: US2 | B13: FLXR83 | C13: 6005 | D13: BPAL | E13: FOB | F13: MERCEDES BENZ | G13: A. LUCO | H13: 45003
A14: US2 | B14: FLXR85 | C14: 6007 | D14: BPAL | E14: FOB | F14: MERCEDES BENZ | G14: A. LUCO | H14: 45003 | J14: BUS QUEMADO
A15: US2 | B15: FLXR86 | C15: 6008 | D15: BPAL | E15: FOB | F15: MERCEDES BENZ | G15: A. LUCO | H15: 45003 | J15: SHCX41 | K15: 45180
A16: US2 | B16: FLXR89 | C16: 6011 | D16: BPAL | E16: FR | F16: MERCEDES BENZ | G16: A. LUCO | H16: 45003 | J16: SHCW73 | K16: 45014
A17: US2 | B17: FLXR90 | C17: 6012 | D17: BPAL | E17: FOB | F17: MERCEDES BENZ | G17: A. LUCO | H17: 45003 | J17: FLXR84 | K17: 45824
A18: US2 | B18: FLXR91 | C18: 6013 | D18: BPAL | E18: FOB | F18: MERCEDES BENZ | G18: A. LUCO | H18: 45003 | J18: FLXR88 | K18: 45967
A19: US2 | B19: FLXR92 | C19: 6014 | D19: BPAL | E19: FOB | F19: MERCEDES BENZ | G19: A. LUCO | H19: 45003
A20: US2 | B20: FLXR93 | C20: 6015 | D20: BPAL | E20: FOB | F20: MERCEDES BENZ | G20: A. LUCO | H20: 45003
A21: US2 | B21: SHCW61 | C21: 6093 | D21: B2 | E21: FOB | F21: VOLVO | G21: A. LUCO | H21: 44982
A22: US2 | B22: SHCW64 | C22: 6096 | D22: B2 | E22: FR | F22: VOLVO | G22: A. LUCO | H22: 44982
A23: US2 | B23: SHCW71 | C23: 6101 | D23: B2 | E23: FOB | F23: VOLVO | G23: A. LUCO | H23: 44982
A24: US2 | B24: SHCW75 | C24: 6104 | D24: B2 | E24: FOB | F24: VOLVO | G24: A. LUCO | H24: 44982
A25: US2 | B25: SHCW76 | C25: 6105 | D25: B2 | E25: FOB | F25: VOLVO | G25: A. LUCO | H25: 44982
A26: US2 | B26: SHCW77 | C26: 6106 | D26: B2 | E26: FOB | F26: VOLVO | G26: A. LUCO | H26: 44982
A27: US2 | B27: SHCW79 | C27: 6108 | D27: B2 | E27: FOB | F27: VOLVO | G27: A. LUCO | H27: 44982
A28: US2 | B28: SHCX26 | C28: 6111 | D28: B2 | E28: FOB | F28: VOLVO | G28: A. LUCO | H28: 44982
A29: US2 | B29: SHCX27 | C29: 6112 | D29: B2 | E29: FOB | F29: VOLVO | G29: A. LUCO | H29: 44982
A30: US2 | B30: SHCX29 | C30: 6114 | D30: B2 | E30: FOB | F30: VOLVO | G30: A. LUCO | H30: 44982
... A64: US2 | B64: FLXS40 | C64: 6025 | D64: BPAL | E64: FS | F64: MERCEDES BENZ | G64: A. LUCO | H64: 45024

Sheet Pie Andino
A1: EMPRESA | B1: PLACA | C1: INTERNO | D1: TIPO BUS | E1: TIPO FLOTA | F1: MARCA CHASIS | G1: TERMINAL OP | H1: Inicio Operación | J1: Cargo | K1: Nombre
A2: US2 | B2: SHCX60 | C2: 5006 | D2: A2 | E2: FOB | F2: VOLVO | G2: PIE ANDINO | H2: 45003 | J2: Jefe de terminal | K2: Patricio Veas
A3: US2 | B3: SHCY42 | C3: 5007 | D3: A2 | E3: FOB | F3: VOLVO | G3: PIE ANDINO | H3: 45003 | J3: Supervisor de Flota | K3: Yorshua
A4: US2 | B4: SHCY60 | C4: 5009 | D4: A2 | E4: FOB | F4: VOLVO | G4: PIE ANDINO | H4: 45003 | J4: Supervisor de Flota | K4: Miguel Tapia
A5: US2 | B5: SHXD57 | C5: 5010 | D5: A2 | E5: FOB | F5: VOLVO | G5: PIE ANDINO | H5: 45003 | J5: Supervisor de Flota | K5: Francisco Imio
A6: US2 | B6: SHXF18 | C6: 5011 | D6: A2 | E6: FOB | F6: VOLVO | G6: PIE ANDINO | H6: 45003
A7: US2 | B7: SHXF36 | C7: 5012 | D7: A2 | E7: FOB | F7: VOLVO | G7: PIE ANDINO | H7: 45003
A8: US2 | B8: SHXF39 | C8: 5013 | D8: A2 | E8: FOB | F8: VOLVO | G8: PIE ANDINO | H8: 45003
A9: US2 | B9: SHXF40 | C9: 5014 | D9: A2 | E9: FOB | F9: VOLVO | G9: PIE ANDINO | H9: 45003 | J9: Etiquetas de fila | K9: CANTIDAD
A10: US2 | B10: SHXG86 | C10: 5015 | D10: A2 | E10: FOB | F10: VOLVO | G10: PIE ANDINO | H10: 45003 | J10: A2 | K10: 15
A11: US2 | B11: SHCY61 | C11: 5016 | D11: A2 | E11: FOB | F11: VOLVO | G11: PIE ANDINO | H11: 45003 | J11: VOLVO | K11: 15
A12: US2 | B12: SHCY63 | C12: 5017 | D12: A2 | E12: FOB | F12: VOLVO | G12: PIE ANDINO | H12: 45003 | J12: B2 | K12: 49
A13: US2 | B13: SHXD82 | C13: 5018 | D13: A2 | E13: FOB | F13: VOLVO | G13: PIE ANDINO | H13: 45003 | J13: MERCEDES BENZ | K13: 12
A14: US2 | B14: SHXD84 | C14: 5019 | D14: A2 | E14: FOB | F14: VOLVO | G14: PIE ANDINO | H14: 45003 | J14: VOLVO | K14: 37
A15: US2 | B15: SHXF22 | C15: 5020 | D15: A2 | E15: FOB | F15: VOLVO | G15: PIE ANDINO | H15: 45003 | J15: BE | K15: 77
A16: US2 | B16: SHCY65 | C16: 5022 | D16: A2 | E16: FOB | F16: VOLVO | G16: PIE ANDINO | H16: 45003 | J16: FOTON | K16: 77
A17: US2 | B17: LBTS75 | C17: 6027 | D17: B2 | E17: FOB | F17: MERCEDES BENZ | G17: PIE ANDINO | H17: 45003 | J17: Total general | K17: 141
A18: US2 | B18: LBTS76 | C18: 6028 | D18: B2 | E18: FR | F18: MERCEDES BENZ | G18: PIE ANDINO | H18: 45003
A19: US2 | B19: LBTS77 | C19: 6029 | D19: B2 | E19: FR | F19: MERCEDES BENZ | G19: PIE ANDINO | H19: 45003
A20: US2 | B20: LBTS78 | C20: 6030 | D20: B2 | E20: FR | F20: MERCEDES BENZ | G20: PIE ANDINO | H20: 45003
A21: US2 | B21: LBTT14 | C21: 6055 | D21: B2 | E21: FR | F21: MERCEDES BENZ | G21: PIE ANDINO | H21: 45024 | J21: BUS QUEMADO
A22: US2 | B22: LBTT22 | C22: 6063 | D22: B2 | E22: FOB | F22: MERCEDES BENZ | G22: PIE ANDINO | H22: 45024 | J22: SHCY48 | K22: 45118
A23: US2 | B23: LCPG33 | C23: 6069 | D23: B2 | E23: FOB | F23: MERCEDES BENZ | G23: PIE ANDINO | H23: 45024 | J23: LBTS93 | K23: 45457
A24: US2 | B24: LCPG47 | C24: 6083 | D24: B2 | E24: FOB | F24: MERCEDES BENZ | G24: PIE ANDINO | H24: 45024 | J24: SHXF38 | K24: 45461
A25: US2 | B25: LCPW28 | C25: 6089 | D25: B2 | E25: FOB | F25: MERCEDES BENZ | G25: PIE ANDINO | H25: 45024 | J25: SPZY72 | K25: 45811
A26: US2 | B26: LCPW29 | C26: 6090 | D26: B2 | E26: FOB | F26: MERCEDES BENZ | G26: PIE ANDINO | H26: 45024
A27: US2 | B27: SHCW69 | C27: 6091 | D27: B2 | E27: FOB | F27: VOLVO | G27: PIE ANDINO | H27: 45003
A28: US2 | B28: SHCW74 | C28: 6092 | D28: B2 | E28: FOB | F28: VOLVO | G28: PIE ANDINO | H28: 45003
A29: US2 | B29: SHCW62 | C29: 6094 | D29: B2 | E29: FR | F29: VOLVO | G29: PIE ANDINO | H29: 44982
A30: US2 | B30: SHCW63 | C30: 6095 | D30: B2 | E30: FR | F30: VOLVO | G30: PIE ANDINO | H30: 44982
A31: US2 | B31: SHCW65 | C31: 6097 | D31: B2 | E31: FOB | F31: VOLVO | G31: PIE ANDINO | H31: 44982
A32: US2 | B32: SHCW67 | C32: 6098 | D32: B2 | E32: FOB | F32: VOLVO | G32: PIE ANDINO | H32: 44982
A33: US2 | B33: SHCW68 | C33: 6099 | D33: B2 | E33: FOB | F33: VOLVO | G33: PIE ANDINO | H33: 44982
A34: US2 | B34: SHCW70 | C34: 6100 | D34: B2 | E34: FOB | F34: VOLVO | G34: PIE ANDINO | H34: 44982
A35: US2 | B35: SHCW72 | C35: 6102 | D35: B2 | E35: FOB | F35: VOLVO | G35: PIE ANDINO | H35: 44982
A36: US2 | B36: SHCW78 | C36: 6107 | D36: B2 | E36: FOB | F36: VOLVO | G36: PIE ANDINO | H36: 44982
A37: US2 | B37: SHCW80 | C37: 6109 | D37: B2 | E37: FOB | F37: VOLVO | G37: PIE ANDINO | H37: 44982
... A142: US2 | B142: SPZY24 | C142: 7065 | D142: BE | E142: FOB | F142: FOTON | G142: PIE ANDINO | H142: 45003

Sheet Juanita
A1: EMPRESA | B1: PLACA | C1: INTERNO | D1: TIPO BUS | E1: TIPO FLOTA | F1: MARCA CHASIS | G1: TERMINAL OP | H1: Inicio Operación | J1: Cargo | K1: Nombre
A2: US2 | B2: LBTS79 | C2: 6031 | D2: B2 | E2: FOB | F2: MERCEDES BENZ | G2: JUANITA | H2: =_xlfn.XLOOKUP(OMJNT[[#This Row],[PLACA]],DitrbFlota[PLACA],DitrbFlota[Inicio Operación]) -> 45003 | J2: Jefe de terminal | K2: Esteban Barra
A3: US2 | B3: LBTS80 | C3: 6032 | D3: B2 | E3: FOB | F3: MERCEDES BENZ | G3: JUANITA | H3: 45024 | J3: Supervisor de Flota | K3: Sebastián Icarte
A4: US2 | B4: LBTS81 | C4: 6033 | D4: B2 | E4: FOB | F4: MERCEDES BENZ | G4: JUANITA | H4: 45003 | J4: Supervisor de Flota | K4: Carlos Oyarce
A5: US2 | B5: LBTS82 | C5: 6034 | D5: B2 | E5: FOB | F5: MERCEDES BENZ | G5: JUANITA | H5: 45003 | J5: Supervisor de Flota | K5: Victor Carvajal
A6: US2 | B6: LBTS83 | C6: 6035 | D6: B2 | E6: FOB | F6: MERCEDES BENZ | G6: JUANITA | H6: 45003
A7: US2 | B7: LBTS85 | C7: 6036 | D7: B2 | E7: FOB | F7: MERCEDES BENZ | G7: JUANITA | H7: 45003
A8: US2 | B8: LBTS86 | C8: 6037 | D8: B2 | E8: FOB | F8: MERCEDES BENZ | G8: JUANITA | H8: =_xlfn.XLOOKUP(OMJNT[[#This Row],[PLACA]],DitrbFlota[PLACA],DitrbFlota[Inicio Operación]) -> 45003 | J8: BUS | K8: CANTIDAD
A9: US2 | B9: LBTS87 | C9: 6038 | D9: B2 | E9: FOB | F9: MERCEDES BENZ | G9: JUANITA | H9: 45003 | J9: B2 | K9: 50
A10: US2 | B10: LBTS88 | C10: 6039 | D10: B2 | E10: FOB | F10: MERCEDES BENZ | G10: JUANITA | H10: =_xlfn.XLOOKUP(OMJNT[[#This Row],[PLACA]],DitrbFlota[PLACA],DitrbFlota[Inicio Operación]) -> 45003 | J10: MERCEDES BENZ | K10: 50
A11: US2 | B11: LBTS89 | C11: 6040 | D11: B2 | E11: FOB | F11: MERCEDES BENZ | G11: JUANITA | H11: 45003 | J11: BE | K11: 122
A12: US2 | B12: LBTS90 | C12: 6041 | D12: B2 | E12: FOB | F12: MERCEDES BENZ | G12: JUANITA | H12: 45003 | J12: FOTON | K12: 97
A13: US2 | B13: LBTS91 | C13: 6042 | D13: B2 | E13: FOB | F13: MERCEDES BENZ | G13: JUANITA | H13: 45003 | J13: YUTONG | K13: 25
A14: US2 | B14: LBTS92 | C14: 6043 | D14: B2 | E14: FOB | F14: MERCEDES BENZ | G14: JUANITA | H14: 45003 | J14: Total general | K14: 172
A15: US2 | B15: LBTS94 | C15: 6045 | D15: B2 | E15: FOB | F15: MERCEDES BENZ | G15: JUANITA | H15: 45003
A16: US2 | B16: LBTS95 | C16: 6046 | D16: B2 | E16: FOB | F16: MERCEDES BENZ | G16: JUANITA | H16: 45003
A17: US2 | B17: LBTS96 | C17: 6047 | D17: B2 | E17: FOB | F17: MERCEDES BENZ | G17: JUANITA | H17: 45003
A18: US2 | B18: LBTS97 | C18: 6048 | D18: B2 | E18: FOB | F18: MERCEDES BENZ | G18: JUANITA | H18: =_xlfn.XLOOKUP(OMJNT[[#This Row],[PLACA]],DitrbFlota[PLACA],DitrbFlota[Inicio Operación]) -> 45003
A19: US2 | B19: LBTS98 | C19: 6049 | D19: B2 | E19: FOB | F19: MERCEDES BENZ | G19: JUANITA | H19: =_xlfn.XLOOKUP(OMJNT[[#This Row],[PLACA]],DitrbFlota[PLACA],DitrbFlota[Inicio Operación]) -> 45003
A20: US2 | B20: LBTS99 | C20: 6050 | D20: B2 | E20: FOB | F20: MERCEDES BENZ | G20: JUANITA | H20: =_xlfn.XLOOKUP(OMJNT[[#This Row],[PLACA]],DitrbFlota[PLACA],DitrbFlota[Inicio Operación]) -> 45003
A21: US2 | B21: LBTT10 | C21: 6051 | D21: B2 | E21: FOB | F21: MERCEDES BENZ | G21: JUANITA | H21: =_xlfn.XLOOKUP(OMJNT[[#This Row],[PLACA]],DitrbFlota[PLACA],DitrbFlota[Inicio Operación]) -> 45003
A22: US2 | B22: LBTT11 | C22: 6052 | D22: B2 | E22: FOB | F22: MERCEDES BENZ | G22: JUANITA | H22: =_xlfn.XLOOKUP(OMJNT[[#This Row],[PLACA]],DitrbFlota[PLACA],DitrbFlota[Inicio Operación]) -> 45003
A23: US2 | B23: LBTT12 | C23: 6053 | D23: B2 | E23: FOB | F23: MERCEDES BENZ | G23: JUANITA | H23: =_xlfn.XLOOKUP(OMJNT[[#This Row],[PLACA]],DitrbFlota[PLACA],DitrbFlota[Inicio Operación]) -> 45003
A24: US2 | B24: LBTT13 | C24: 6054 | D24: B2 | E24: FOB | F24: MERCEDES BENZ | G24: JUANITA | H24: =_xlfn.XLOOKUP(OMJNT[[#This Row],[PLACA]],DitrbFlota[PLACA],DitrbFlota[Inicio Operación]) -> 45003
A25: US2 | B25: LBTT15 | C25: 6056 | D25: B2 | E25: FR | F25: MERCEDES BENZ | G25: JUANITA | H25: 45024
A26: US2 | B26: LBTT16 | C26: 6057 | D26: B2 | E26: FOB | F26: MERCEDES BENZ | G26: JUANITA | H26: =_xlfn.XLOOKUP(OMJNT[[#This Row],[PLACA]],DitrbFlota[PLACA],DitrbFlota[Inicio Operación]) -> 45024
A27: US2 | B27: LBTT17 | C27: 6058 | D27: B2 | E27: FOB | F27: MERCEDES BENZ | G27: JUANITA | H27: 45024
A28: US2 | B28: LBTT18 | C28: 6059 | D28: B2 | E28: FOB | F28: MERCEDES BENZ | G28: JUANITA | H28: 45024
A29: US2 | B29: LBTT19 | C29: 6060 | D29: B2 | E29: FOB | F29: MERCEDES BENZ | G29: JUANITA | H29: =_xlfn.XLOOKUP(OMJNT[[#This Row],[PLACA]],DitrbFlota[PLACA],DitrbFlota[Inicio Operación]) -> 45003
A30: US2 | B30: LBTT20 | C30: 6061 | D30: B2 | E30: FOB | F30: MERCEDES BENZ | G30: JUANITA | H30: =_xlfn.XLOOKUP(OMJNT[[#This Row],[PLACA]],DitrbFlota[PLACA],DitrbFlota[Inicio Operación]) -> 45024
A31: US2 | B31: LBTT21 | C31: 6062 | D31: B2 | E31: FOB | F31: MERCEDES BENZ | G31: JUANITA | H31: 45024
A32: US2 | B32: LBTT23 | C32: 6064 | D32: B2 | E32: FOB | F32: MERCEDES BENZ | G32: JUANITA | H32: 45024
A33: US2 | B33: LBTT24 | C33: 6065 | D33: B2 | E33: FOB | F33: MERCEDES BENZ | G33: JUANITA | H33: 45024
A34: US2 | B34: LBTT25 | C34: 6066 | D34: B2 | E34: FOB | F34: MERCEDES BENZ | G34: JUANITA | H34: =_xlfn.XLOOKUP(OMJNT[[#This Row],[PLACA]],DitrbFlota[PLACA],DitrbFlota[Inicio Operación]) -> 45024
A35: US2 | B35: LCPG31 | C35: 6067 | D35: B2 | E35: FOB | F35: MERCEDES BENZ | G35: JUANITA | H35: 45024
A36: US2 | B36: LCPG32 | C36: 6068 | D36: B2 | E36: FOB | F36: MERCEDES BENZ | G36: JUANITA | H36: =_xlfn.XLOOKUP(OMJNT[[#This Row],[PLACA]],DitrbFlota[PLACA],DitrbFlota[Inicio Operación]) -> 45024
A37: US2 | B37: LCPG34 | C37: 6070 | D37: B2 | E37: FOB | F37: MERCEDES BENZ | G37: JUANITA | H37: 45024
A38: US2 | B38: LCPG36 | C38: 6072 | D38: B2 | E38: FOB | F38: MERCEDES BENZ | G38: JUANITA | H38: 45024
A39: US2 | B39: LCPG37 | C39: 6073 | D39: B2 | E39: FOB | F39: MERCEDES BENZ | G39: JUANITA | H39: 45024
A40: US2 | B40: LCPG38 | C40: 6074 | D40: B2 | E40: FOB | F40: MERCEDES BENZ | G40: JUANITA | H40: 45024
...

Sheet Flota Soporte
A1: EMPRESA | B1: PLACA | C1: INTERNO | D1: TIPO BUS | E1: TIPO FLOTA | F1: MARCA CHASIS | G1: TERMINAL APOYO | H1: Inicio Operación | I1: Observaciones | J1: ACTUALIZACIÓN | K1: 46184
A2: US1 | B2: FLXP66 | C2: 2026 | D2: BPAL | E2: FS | F2: MERCEDES BENZ | G2: STA MARTA | H2: 45024
A3: US1 | B3: FLXP67 | C3: 2027 | D3: BPAL | E3: FS | F3: MERCEDES BENZ | G3: STA MARTA | H3: 45024 | I3: Bus FS / eliminado del consolidado
A4: US1 | B4: FLXP68 | C4: 2028 | D4: BPAL | E4: FS | F4: MERCEDES BENZ | G4: STA MARTA | H4: 45024
A5: US1 | B5: FLXP69 | C5: 2029 | D5: BPAL | E5: FS | F5: MERCEDES BENZ | G5: STA MARTA | H5: 45024
A6: US1 | B6: FLXP70 | C6: 2030 | D6: BPAL | E6: FS | F6: MERCEDES BENZ | G6: STA MARTA | H6: 45024
A7: US1 | B7: FLXP71 | C7: 2031 | D7: BPAL | E7: FS | F7: MERCEDES BENZ | G7: STA MARTA | H7: 45024
A8: US1 | B8: FLXP72 | C8: 2032 | D8: BPAL | E8: FS | F8: MERCEDES BENZ | G8: STA MARTA | H8: 45024
A9: US1 | B9: FLXP73 | C9: 2033 | D9: BPAL | E9: FS | F9: MERCEDES BENZ | G9: STA MARTA | H9: 45024
A10: US1 | B10: FLXP75 | C10: 2034 | D10: BPAL | E10: FS | F10: MERCEDES BENZ | G10: STA MARTA | H10: 45024
A11: US1 | B11: FLXP76 | C11: 2035 | D11: BPAL | E11: FS | F11: MERCEDES BENZ | G11: STA MARTA | H11: 45024
A12: US1 | B12: FLXP77 | C12: 2036 | D12: BPAL | E12: FS | F12: MERCEDES BENZ | G12: STA MARTA | H12: 45024
A13: US1 | B13: FLXP78 | C13: 2037 | D13: BPAL | E13: FS | F13: MERCEDES BENZ | G13: STA MARTA | H13: 45024
A14: US1 | B14: FLXP79 | C14: 2038 | D14: BPAL | E14: FS | F14: MERCEDES BENZ | G14: STA MARTA | H14: 45024
A15: US1 | B15: FLXP80 | C15: 2039 | D15: BPAL | E15: FS | F15: MERCEDES BENZ | G15: STA MARTA | H15: 45024
... A21: US2 | B21: FLXR76 | C21: 6019 | D21: BPAL | E21: FS | F21: MERCEDES BENZ | G21: A. LUCO | H21: 45024
A22: US2 | B22: FLXR77 | C22: 6020 | D22: BPAL | E22: FS | F22: MERCEDES BENZ | G22: A. LUCO | H22: 45024 | I22: BUS PRÉSTAMO DE PIE ANDINO
A23: US2 | B23: FLXS32 | C23: 6021 | D23: BPAL | E23: FS | F23: MERCEDES BENZ | G23: A. LUCO | H23: 45024 | I23: BUS PRÉSTAMO DE PIE ANDINO
A24: US2 | B24: FLXS38 | C24: 6023 | D24: BPAL | E24: FS | F24: MERCEDES BENZ | G24: A. LUCO | H24: 45024 | I24: BUS PRÉSTAMO DE PIE ANDINO
A25: US2 | B25: FLXS41 | C25: 6026 | D25: BPAL | E25: FS | F25: MERCEDES BENZ | G25: A. LUCO | H25: 45024 | I25: BUS PRÉSTAMO DE PIE ANDINO
A26: US2 | B26: FLXS33 | C26: 6022 | D26: BPAL | E26: FS | F26: MERCEDES BENZ | G26: A. LUCO | H26: 45024 | I26: BUS PRÉSTAMO DE PIE ANDINO
A27: US2 | B27: FLXS39 | C27: 6024 | D27: BPAL | E27: FS | F27: MERCEDES BENZ | G27: A. LUCO | H27: 45024 | I27: BUS PRÉSTAMO DE PIE ANDINO
A28: US2 | B28: FLXS40 | C28: 6025 | D28: BPAL | E28: FS | F28: MERCEDES BENZ | G28: A. LUCO | H28: 45024 | I28: BUS PRÉSTAMO DE PIE ANDINO

Sheet Flota Auxiliar
A1: EMPRESA | B1: PLACA | C1: INTERNO | D1: TIPO BUS | E1: TIPO FLOTA | F1: MARCA CHASIS | G1: TERMINAL APOYO | H1: Inicio Operación | I1: ORIGEN | J1: Observaciones | K1: ACTUALIZACIÓN | L1: 46184
A2: US1 | B2: FLXS60 | C2: 2017 | D2: BPAL | E2: FAUX | F2: MERCEDES BENZ | G2: STA MARTA | H2: 45038 | I2: PROVISIÓN | J2: 45694
A3: US1 | B3: FLXS62 | C3: 2019 | D3: BPAL | E3: FAUX | F3: MERCEDES BENZ | G3: STA MARTA | H3: 45038 | I3: PROVISIÓN | J3: 45694

Sheet Tablas
A3: TERMINAL OP | B3: MARCA CHASIS | C3: TIPO BUS | D3: Cuenta de INTERNO | G3: Cuenta de TERMINAL OP | H3: Etiquetas de columna
A4: A. LUCO | B4: MERCEDES BENZ | C4: BPAL | D4: 25 | G4: Etiquetas de fila | H4: A2 | I4: B2 | J4: BE | K4: BPAL | L4: C2 | M4: Total general
A5: A. LUCO | B5: VOLVO | C5: A2 | D5: 6 | G5: US1 | H5: 37 | I5: 71 | J5: 141 | K5: 45 | L5: 69 | M5: 363
A6: A. LUCO | B6: VOLVO | C6: B2 | D6: 33 | G6: CONDELL | H6: 10 | I6: 12 | J6: 75 | L6: 31 | M6: 128
A7: CONDELL | B7: FOTON | C7: BE | D7: 75 | G7: EL RETIRO | H7: 11 | I7: 28 | L7: 19 | M7: 58
A8: CONDELL | B8: MERCEDES BENZ | C8: B2 | D8: 12 | G8: SANTA MARGARITA | I8: 9 | L8: 19 | M8: 28
A9: CONDELL | B9: MERCEDES BENZ | C9: C2 | D9: 24 | G9: STA MARTA | H9: 16 | I9: 22 | J9: 66 | K9: 45 | M9: 149
A10: CONDELL | B10: VOLVO | C10: A2 | D10: 10 | G10: US2 | H10: 21 | I10: 132 | J10: 199 | K10: 25 | M10: 377
A11: CONDELL | B11: VOLVO | C11: C2 | D11: 7 | G11: A. LUCO | H11: 6 | I11: 33 | K11: 25 | M11: 64
A12: EL RETIRO | B12: SCANIA | C12: B2 | D12: 28 | G12: PIE ANDINO | H12: 15 | I12: 39 | J12: 77 | M12: 131
A13: EL RETIRO | B13: VOLVO | C13: A2 | D13: 11 | G13: JUANITA | I13: 60 | J13: 122 | M13: 182
A14: EL RETIRO | B14: VOLVO | C14: C2 | D14: 19 | G14: Total general | H14: 58 | I14: 203 | J14: 340 | K14: 70 | L14: 69 | M14: 740
A15: JUANITA | B15: FOTON | C15: BE | D15: 97
A16: JUANITA | B16: MERCEDES BENZ | C16: B2 | D16: 60
A17: JUANITA | B17: YUTONG | C17: BE | D17: 25
A18: PIE ANDINO | B18: FOTON | C18: BE | D18: 77
A19: PIE ANDINO | B19: MERCEDES BENZ | C19: B2 | D19: 2 | G19: Cuenta de PLACA | H19: Etiquetas de columna
A20: PIE ANDINO | B20: VOLVO | C20: A2 | D20: 15 | G20: Etiquetas de fila | H20: FOTON | I20: MERCEDES BENZ | J20: SCANIA | K20: VOLVO | L20: YUTONG | M20: Total general
A21: PIE ANDINO | B21: VOLVO | C21: B2 | D21: 37 | G21: US1 | H21: 141 | I21: 100 | J21: 40 | K21: 82 | M21: 363
A22: SANTA MARGARITA | B22: SCANIA | C22: B2 | D22: 9 | G22: ALCON | H22: 75 | I22: 36 | K22: 17 | M22: 128
A23: SANTA MARGARITA | B23: VOLVO | C23: C2 | D23: 19 | G23: ALRET | J23: 37 | K23: 49 | M23: 86
A24: STA MARTA | B24: FOTON | C24: BE | D24: 66 | G24: ALSMT | H24: 66 | I24: 64 | J24: 3 | K24: 16 | M24: 149
A25: STA MARTA | B25: MERCEDES BENZ | C25: B2 | D25: 22 | G25: US2 | H25: 174 | I25: 87 | K25: 91 | L25: 25 | M25: 377
A26: STA MARTA | B26: MERCEDES BENZ | C26: BPAL | D26: 42 | G26: OMJJA | I26: 25 | K26: 39 | M26: 64
A27: STA MARTA | B27: SCANIA | C27: BPAL | D27: 3 | G27: OMJNT | H27: 97 | I27: 50 | L27: 25 | M27: 172
A28: STA MARTA | B28: VOLVO | C28: A2 | D28: 16 | G28: OMPAN | H28: 77 | I28: 12 | K28: 52 | M28: 141
A29: Total general | D29: 740 | G29: Total general | H29: 315 | I29: 187 | J29: 40 | K29: 173 | L29: 25 | M29: 740
G41: Cuenta de ORIGEN | H41: Etiquetas de columna
G42: Etiquetas de fila | H42: FOB | I42: FR | J42: FS | K42: FAUX | L42: Total general | M42: US1
G43: US1 | H43: 308 | I43: 37 | J43: 16 | K43: 2 | L43: 363 | M43: FOB | N43: =GETPIVOTDATA("ORIGEN",$G$41,"EMPRESA","US1","TIPO FLOTA","FOB")/GETPIVOTDATA("ORIGEN",$G$41,"EMPRESA","US1") -> 0.84848485
G44: CONDELL | H44: 84 | I44: 21 | L44: 105 | M44: FR | N44: =I43/H43 -> 0.12012987
G45: EL RETIRO | H45: 78 | I45: 3 | L45: 81 | M45: FS | N45: =GETPIVOTDATA("ORIGEN",$G$41,"EMPRESA","US1","TIPO FLOTA","FS")/GETPIVOTDATA("ORIGEN",$G$41,"EMPRESA","US1") -> 0.044077135
G46: SANTA MARGARITA | H46: 28 | L46: 28
G47: STA MARTA | H47: 118 | I47: 13 | J47: 16 | K47: 2 | L47: 149 | M47: US2
G48: US2 | H48: 336 | I48: 30 | J48: 11 | L48: 377 | M48: FOB | N48: =GETPIVOTDATA("ORIGEN",$G$41,"EMPRESA","US2","TIPO FLOTA","FOB")/GETPIVOTDATA("ORIGEN",$G$41,"EMPRESA","US2") -> 0.89124668
G49: A. LUCO | H49: 51 | I49: 2 | J49: 11 | L49: 64 | M49: FR | N49: =I48/H48 -> 0.089285714
G50: JUANITA | H50: 164 | I50: 20 | L50: 184 | M50: FS | N50: =GETPIVOTDATA("ORIGEN",$G$41,"EMPRESA","US2","TIPO FLOTA","FS")/GETPIVOTDATA("ORIGEN",$G$41,"EMPRESA","US2") -> 0.029177719
G51: PIE ANDINO | H51: 121 | I51: 8 | L51: 129
G52: Total general | H52: 644 | I52: 67 | J52: 27 | K52: 2 | L52: 740

Sheet Dinámicas
C2: ALFA | K2: OMEGA
C4: El Retiro | D4: Cantidad | F4: Sta Margarita | G4: Cantidad | K4: A Luco | L4: Cantidad | N4: Pie Andino | O4: Cantidad
C5: A2 | D5: 11 | F5: B2 | G5: 9 | K5: A2 | L5: 6 | N5: A2 | O5: 15
C6: VOLVO | D6: 11 | F6: SCANIA | G6: 9 | K6: VOLVO | L6: 6 | N6: VOLVO | O6: 15
C7: B2 | D7: 28 | F7: C2 | G7: 19 | K7: FOB | L7: 6 | N7: FOB | O7: 15
C8: SCANIA | D8: 28 | F8: VOLVO | G8: 19 | K8: B2 | L8: 33 | N8: B2 | O8: 49
C9: C2 | D9: 19 | F9: Total general | G9: 28 | K9: VOLVO | L9: 33 | N9: MERCEDES BENZ | O9: 12
C10: VOLVO | D10: 19 | K10: FOB | L10: 32 | N10: VOLVO | O10: 37
C11: Total general | D11: 58 | F11: Coca-Cola | G11: Cantidad | K11: FR | L11: 1 | N11: FOB | O11: 34
F12: (en blanco) | K12: BPAL | L12: 24 | N12: FR | O12: 3
F13: (en blanco) | K13: MERCEDES BENZ | L13: 24 | N13: BE | O13: 77
F14: (en blanco) | K14: FOB | L14: 12 | N14: FOTON | O14: 77
C15: Condell | D15: Cantidad | F15: Total general | K15: FR | L15: 1 | N15: Total general | O15: 141
C16: A2 | D16: 10 | K16: FS | L16: 11
C17: VOLVO | D17: 10 | F17: Sta Marta | G17: Cantidad | K17: Total general | L17: 63
C18: B2 | D18: 12 | F18: B2 | G18: 22
C19: MERCEDES BENZ | D19: 12 | F19: MERCEDES BENZ | G19: 22
C20: BE | D20: 75 | F20: FOB | G20: 18
C21: FOTON | D21: 75 | F21: FR | G21: 4
C22: FOB | D22: 57 | F22: BPAL | G22: 43 | K22: Juanita | L22: Cantidad
C23: FR | D23: 18 | F23: SCANIA | G23: 3 | K23: B2 | L23: 50
C24: C2 | D24: 31 | F24: FOB | G24: 2 | K24: MERCEDES BENZ | L24: 50
C25: MERCEDES BENZ | D25: 24 | F25: FR | G25: 1 | K25: FOB | L25: 49
C26: VOLVO | D26: 7 | F26: MERCEDES BENZ | G26: 40 | K26: FR | L26: 1
C27: Total general | D27: 128 | F27: FOB | G27: 22 | K27: BE | L27: 122
F28: FR | G28: 2 | K28: FOTON | L28: 97
F29: FS | G29: 16 | K29: YUTONG | L29: 25
F30: A2 | G30: 16 | K30: Total general | L30: 172
F31: VOLVO | G31: 16
F32: FOB | G32: 16
F33: BE | G33: 66
F34: FOTON | G34: 66
F35: FOB | G35: 60
F36: FR | G36: 6
F37: Total general | G37: 147

Sheet Resumen Distribución
D1: BE-FOTON | E1: A2-VOLVO | F1: B2-VOLVO | G1: C2-VOLVO | H1: B2-MERCEDES BENZ | I1: BPAL-MERCEDES BENZ | J1: C2-MERCEDES BENZ | K1: B2-SCANIA | L1: BPAL-SCANIA | M1: BE-YUTONG
B2: Empresa | C2: Terminal | D2: Foton | E2: Volvo | H2: Mercedes Benz | K2: Scania | M2: Yutong | N2: Total | S2: Terminal | T2: PPU | U2: Modelo | V2: Motivo | W2: Observación
D3: BE | E3: A2 | F3: B2 | G3: C2 | H3: B2 | I3: BPAL | J3: C2 | K3: B2 | L3: BPAL | M3: BE | S3: Santa Marta | T3: FLXS62 | U3: MB - BPAL | V3: Sistema de Motor | W3: MOTOR MALO
A4: EL RETIRO | B4: Alfa | C4: El Retiro | D4: =COUNTIFS(DitrbFlota[TERMINAL OP],'Resumen Distribución'!$A4,DitrbFlota[Busqueda],'Resumen Distribución'!D$1) -> 0 | E4: =COUNTIFS(DitrbFlota[TERMINAL OP],'Resumen Distribución'!$A4,DitrbFlota[Busqueda],'Resumen Distribución'!E$1) -> 11 | F4: =COUNTIFS(DitrbFlota[TERMINAL OP],'Resumen Distribución'!$A4,DitrbFlota[Busqueda],'Resumen Distribución'!F$1) -> 0 | G4: =COUNTIFS(DitrbFlota[TERMINAL OP],'Resumen Distribución'!$A4,DitrbFlota[Busqueda],'Resumen Distribución'!G$1) -> 19 | H4: =COUNTIFS(DitrbFlota[TERMINAL OP],'Resumen Distribución'!$A4,DitrbFlota[Busqueda],'Resumen Distribución'!H$1) -> 0 | I4: =COUNTIFS(DitrbFlota[TERMINAL OP],'Resumen Distribución'!$A4,DitrbFlota[Busqueda],'Resumen Distribución'!I$1) -> 0 | J4: =COUNTIFS(DitrbFlota[TERMINAL OP],'Resumen Distribución'!$A4,DitrbFlota[Busqueda],'Resumen Distribución'!J$1) -> 0 | K4: =COUNTIFS(DitrbFlota[TERMINAL OP],'Resumen Distribución'!$A4,DitrbFlota[Busqueda],'Resumen Distribución'!K$1) -> 28 | ... M4: =COUNTIFS(DitrbFlota[TERMINAL OP],'Resumen Distribución'!$A4,DitrbFlota[Busqueda],'Resumen Distribución'!M$1) -> 0 | N4: =SUM(D4:M4) -> 58 | S4: Santa Marta | T4: FLXS60 | U4: MB - BPAL | V4: Sistema de Motor | W4: MOTOR MALO
A5: CONDELL | C5: Condell | D5: =COUNTIFS(DitrbFlota[TERMINAL OP],'Resumen Distribución'!$A5,DitrbFlota[Busqueda],'Resumen Distribución'!D$1) -> 75 | E5: =COUNTIFS(DitrbFlota[TERMINAL OP],'Resumen Distribución'!$A5,DitrbFlota[Busqueda],'Resumen Distribución'!E$1) -> 10 | F5: =COUNTIFS(DitrbFlota[TERMINAL OP],'Resumen Distribución'!$A5,DitrbFlota[Busqueda],'Resumen Distribución'!F$1) -> 0 | G5: =COUNTIFS(DitrbFlota[TERMINAL OP],'Resumen Distribución'!$A5,DitrbFlota[Busqueda],'Resumen Distribución'!G$1) -> 7 | H5: =COUNTIFS(DitrbFlota[TERMINAL OP],'Resumen Distribución'!$A5,DitrbFlota[Busqueda],'Resumen Distribución'!H$1) -> 12 | I5: =COUNTIFS(DitrbFlota[TERMINAL OP],'Resumen Distribución'!$A5,DitrbFlota[Busqueda],'Resumen Distribución'!I$1) -> 0 | J5: =COUNTIFS(DitrbFlota[TERMINAL OP],'Resumen Distribución'!$A5,DitrbFlota[Busqueda],'Resumen Distribución'!J$1) -> 24 | K5: =COUNTIFS(DitrbFlota[TERMINAL OP],'Resumen Distribución'!$A5,DitrbFlota[Busqueda],'Resumen Distribución'!K$1) -> 0 | ... M5: =COUNTIFS(DitrbFlota[TERMINAL OP],'Resumen Distribución'!$A5,DitrbFlota[Busqueda],'Resumen Distribución'!M$1) -> 0 | N5: =SUM(D5:M5) -> 128 | S5: Condell | T5: LFGJ96 | U5: MB - C2 | V5: Quemado | W5: No Entregado
A6: STA MARTA | C6: Santa Marta | D6: =COUNTIFS(DitrbFlota[TERMINAL OP],'Resumen Distribución'!$A6,DitrbFlota[Busqueda],'Resumen Distribución'!D$1) -> 66 | E6: =COUNTIFS(DitrbFlota[TERMINAL OP],'Resumen Distribución'!$A6,DitrbFlota[Busqueda],'Resumen Distribución'!E$1) -> 16 | F6: =COUNTIFS(DitrbFlota[TERMINAL OP],'Resumen Distribución'!$A6,DitrbFlota[Busqueda],'Resumen Distribución'!F$1) -> 0 | G6: =COUNTIFS(DitrbFlota[TERMINAL OP],'Resumen Distribución'!$A6,DitrbFlota[Busqueda],'Resumen Distribución'!G$1) -> 0 | H6: =COUNTIFS(DitrbFlota[TERMINAL OP],'Resumen Distribución'!$A6,DitrbFlota[Busqueda],'Resumen Distribución'!H$1) -> 22 | I6: =COUNTIFS(DitrbFlota[TERMINAL OP],'Resumen Distribución'!$A6,DitrbFlota[Busqueda],'Resumen Distribución'!I$1) -> 42 | J6: =COUNTIFS(DitrbFlota[TERMINAL OP],'Resumen Distribución'!$A6,DitrbFlota[Busqueda],'Resumen Distribución'!J$1) -> 0 | K6: =COUNTIFS(DitrbFlota[TERMINAL OP],'Resumen Distribución'!$A6,DitrbFlota[Busqueda],'Resumen Distribución'!K$1) -> 0 | ... M6: =COUNTIFS(DitrbFlota[TERMINAL OP],'Resumen Distribución'!$A6,DitrbFlota[Busqueda],'Resumen Distribución'!M$1) -> 0 | N6: =SUM(D6:M6) -> 149 | S6: Aguirre Luco | T6: SHCW73 | U6: Volvo - B2 | V6: SINIESTRO | W6: Bus Quemado
A7: SANTA MARGARITA | C7: Santa Margarita | D7: =COUNTIFS(DitrbFlota[TERMINAL OP],'Resumen Distribución'!$A7,DitrbFlota[Busqueda],'Resumen Distribución'!D$1) -> 0 | E7: =COUNTIFS(DitrbFlota[TERMINAL OP],'Resumen Distribución'!$A7,DitrbFlota[Busqueda],'Resumen Distribución'!E$1) -> 0 | F7: =COUNTIFS(DitrbFlota[TERMINAL OP],'Resumen Distribución'!$A7,DitrbFlota[Busqueda],'Resumen Distribución'!F$1) -> 0 | G7: =COUNTIFS(DitrbFlota[TERMINAL OP],'Resumen Distribución'!$A7,DitrbFlota[Busqueda],'Resumen Distribución'!G$1) -> 19 | H7: =COUNTIFS(DitrbFlota[TERMINAL OP],'Resumen Distribución'!$A7,DitrbFlota[Busqueda],'Resumen Distribución'!H$1) -> 0 | I7: =COUNTIFS(DitrbFlota[TERMINAL OP],'Resumen Distribución'!$A7,DitrbFlota[Busqueda],'Resumen Distribución'!I$1) -> 0 | J7: =COUNTIFS(DitrbFlota[TERMINAL OP],'Resumen Distribución'!$A7,DitrbFlota[Busqueda],'Resumen Distribución'!J$1) -> 0 | K7: =COUNTIFS(DitrbFlota[TERMINAL OP],'Resumen Distribución'!$A7,DitrbFlota[Busqueda],'Resumen Distribución'!K$1) -> 9 | ... M7: =COUNTIFS(DitrbFlota[TERMINAL OP],'Resumen Distribución'!$A7,DitrbFlota[Busqueda],'Resumen Distribución'!M$1) -> 0 | N7: =SUM(D7:M7) -> 28 | S7: Aguirre Luco | T7: SHCX41 | U7: Volvo - A2 | V7: SINIESTRO | W7: Bus Quemado
A8: A. LUCO | B8: Omega | C8: Aguirre Luco | D8: =COUNTIFS(DitrbFlota[TERMINAL OP],'Resumen Distribución'!$A8,DitrbFlota[Busqueda],'Resumen Distribución'!D$1) -> 0 | E8: =COUNTIFS(DitrbFlota[TERMINAL OP],'Resumen Distribución'!$A8,DitrbFlota[Busqueda],'Resumen Distribución'!E$1) -> 6 | F8: =COUNTIFS(DitrbFlota[TERMINAL OP],'Resumen Distribución'!$A8,DitrbFlota[Busqueda],'Resumen Distribución'!F$1) -> 33 | G8: =COUNTIFS(DitrbFlota[TERMINAL OP],'Resumen Distribución'!$A8,DitrbFlota[Busqueda],'Resumen Distribución'!G$1) -> 0 | H8: =COUNTIFS(DitrbFlota[TERMINAL OP],'Resumen Distribución'!$A8,DitrbFlota[Busqueda],'Resumen Distribución'!H$1) -> 0 | I8: =COUNTIFS(DitrbFlota[TERMINAL OP],'Resumen Distribución'!$A8,DitrbFlota[Busqueda],'Resumen Distribución'!I$1) -> 25 | J8: =COUNTIFS(DitrbFlota[TERMINAL OP],'Resumen Distribución'!$A8,DitrbFlota[Busqueda],'Resumen Distribución'!J$1) -> 0 | K8: =COUNTIFS(DitrbFlota[TERMINAL OP],'Resumen Distribución'!$A8,DitrbFlota[Busqueda],'Resumen Distribución'!K$1) -> 0 | ... M8: =COUNTIFS(DitrbFlota[TERMINAL OP],'Resumen Distribución'!$A8,DitrbFlota[Busqueda],'Resumen Distribución'!M$1) -> 0 | N8: =SUM(D8:M8) -> 64 | S8: Pie Andino | T8: SHCY48 | U8: Volvo - A2 | V8: SINIESTRO | W8: Bus Quemado
A9: PIE ANDINO | C9: Pie Andino | D9: =COUNTIFS(DitrbFlota[TERMINAL OP],'Resumen Distribución'!$A9,DitrbFlota[Busqueda],'Resumen Distribución'!D$1) -> 75 | E9: =COUNTIFS(DitrbFlota[TERMINAL OP],'Resumen Distribución'!$A9,DitrbFlota[Busqueda],'Resumen Distribución'!E$1) -> 15 | F9: =COUNTIFS(DitrbFlota[TERMINAL OP],'Resumen Distribución'!$A9,DitrbFlota[Busqueda],'Resumen Distribución'!F$1) -> 37 | G9: =COUNTIFS(DitrbFlota[TERMINAL OP],'Resumen Distribución'!$A9,DitrbFlota[Busqueda],'Resumen Distribución'!G$1) -> 0 | H9: =COUNTIFS(DitrbFlota[TERMINAL OP],'Resumen Distribución'!$A9,DitrbFlota[Busqueda],'Resumen Distribución'!H$1) -> 2 | I9: =COUNTIFS(DitrbFlota[TERMINAL OP],'Resumen Distribución'!$A9,DitrbFlota[Busqueda],'Resumen Distribución'!I$1) -> 0 | J9: =COUNTIFS(DitrbFlota[TERMINAL OP],'Resumen Distribución'!$A9,DitrbFlota[Busqueda],'Resumen Distribución'!J$1) -> 0 | K9: =COUNTIFS(DitrbFlota[TERMINAL OP],'Resumen Distribución'!$A9,DitrbFlota[Busqueda],'Resumen Distribución'!K$1) -> 0 | ... M9: =COUNTIFS(DitrbFlota[TERMINAL OP],'Resumen Distribución'!$A9,DitrbFlota[Busqueda],'Resumen Distribución'!M$1) -> 0 | N9: =SUM(D9:M9) -> 129 | S9: Juanita | T9: LCPG35 | U9: MB - B2 | V9: MOTOR | W9: No Entregado
A10: JUANITA | C10: Juanita | D10: =COUNTIFS(DitrbFlota[TERMINAL OP],'Resumen Distribución'!$A10,DitrbFlota[Busqueda],'Resumen Distribución'!D$1) -> 99 | E10: =COUNTIFS(DitrbFlota[TERMINAL OP],'Resumen Distribución'!$A10,DitrbFlota[Busqueda],'Resumen Distribución'!E$1) -> 0 | F10: =COUNTIFS(DitrbFlota[TERMINAL OP],'Resumen Distribución'!$A10,DitrbFlota[Busqueda],'Resumen Distribución'!F$1) -> 0 | G10: =COUNTIFS(DitrbFlota[TERMINAL OP],'Resumen Distribución'!$A10,DitrbFlota[Busqueda],'Resumen Distribución'!G$1) -> 0 | H10: =COUNTIFS(DitrbFlota[TERMINAL OP],'Resumen Distribución'!$A10,DitrbFlota[Busqueda],'Resumen Distribución'!H$1) -> 60 | I10: =COUNTIFS(DitrbFlota[TERMINAL OP],'Resumen Distribución'!$A10,DitrbFlota[Busqueda],'Resumen Distribución'!I$1) -> 0 | J10: =COUNTIFS(DitrbFlota[TERMINAL OP],'Resumen Distribución'!$A10,DitrbFlota[Busqueda],'Resumen Distribución'!J$1) -> 0 | K10: =COUNTIFS(DitrbFlota[TERMINAL OP],'Resumen Distribución'!$A10,DitrbFlota[Busqueda],'Resumen Distribución'!K$1) -> 0 | ... M10: =COUNTIFS(DitrbFlota[TERMINAL OP],'Resumen Distribución'!$A10,DitrbFlota[Busqueda],'Resumen Distribución'!M$1) -> 25 | N10: =SUM(D10:M10) -> 184
B11: Total | D11: =SUM(D4:D10) -> 315 | E11: =SUM(E4:E10) -> 58 | F11: =SUM(F4:F10) -> 70 | G11: =SUM(G4:G10) -> 45 | H11: =SUM(H4:H10) -> 96 | I11: =SUM(I4:I10) -> 67 | J11: =SUM(J4:J10) -> 24 | K11: =SUM(K4:K10) -> 37 | ... M11: =SUM(M4:M10) -> 25 | N11: =SUM(D11:M11) -> 740
A13: Para envia
B14: Inicio Operación | C14: Terminal
B15: 44912 | C15: EL RETIRO
B16: 44928 | C16: STA MARGARITA
B17: 44933 | C17: CONDELL
B18: 44982 | C18: A. LUCO
B19: 44991 | C19: CONDELL
B20: 45003 | C20: PIE ANDINO
B21: 45007 | C21: CONDELL
B22: 45024 | C22: JUANITA
B23: 45038 | C23: SANTA MARTA
B34: Empresa | C34: Terminal | D34: Foton | E34: Volvo | H34: Mercedes Benz | K34: Scania | M34: Yutong
D35: BE | E35: A2 | F35: B2 | G35: C2 | H35: B2 | I35: BPAL | J35: C2 | K35: B2 | L35: BPAL | M35: BE
B36: Alfa | C36: El Retiro | D36: =+IFERROR(D4/D$11,0) -> 0 | E36: =+IFERROR(E4/E$11,0) -> 0.18965517 | F36: =+IFERROR(F4/F$11,0) -> 0 | G36: =+IFERROR(G4/G$11,0) -> 0.42222222 | H36: =+IFERROR(H4/H$11,0) -> 0 | I36: =+IFERROR(I4/I$11,0) -> 0 | J36: =+IFERROR(J4/J$11,0) -> 0 | K36: =+IFERROR(K4/K$11,0) -> 0.75675676 | ... M36: =+IFERROR(M4/M$11,0) -> 0
C37: Condell | D37: =+IFERROR(D5/D$11,0) -> 0.23809524 | E37: =+IFERROR(E5/E$11,0) -> 0.17241379 | F37: =+IFERROR(F5/F$11,0) -> 0 | G37: =+IFERROR(G5/G$11,0) -> 0.15555556 | H37: =+IFERROR(H5/H$11,0) -> 0.125 | I37: =+IFERROR(I5/I$11,0) -> 0 | J37: =+IFERROR(J5/J$11,0) -> 1 | K37: =+IFERROR(K5/K$11,0) -> 0 | ... M37: =+IFERROR(M5/M$11,0) -> 0
C38: Santa Marta | D38: =+IFERROR(D6/D$11,0) -> 0.20952381 | E38: =+IFERROR(E6/E$11,0) -> 0.27586207 | F38: =+IFERROR(F6/F$11,0) -> 0 | G38: =+IFERROR(G6/G$11,0) -> 0 | H38: =+IFERROR(H6/H$11,0) -> 0.22916667 | I38: =+IFERROR(I6/I$11,0) -> 0.62686567 | J38: =+IFERROR(J6/J$11,0) -> 0 | K38: =+IFERROR(K6/K$11,0) -> 0 | ... M38: =+IFERROR(M6/M$11,0) -> 0
C39: Santa Margarita | D39: =+IFERROR(D7/D$11,0) -> 0 | E39: =+IFERROR(E7/E$11,0) -> 0 | F39: =+IFERROR(F7/F$11,0) -> 0 | G39: =+IFERROR(G7/G$11,0) -> 0.42222222 | H39: =+IFERROR(H7/H$11,0) -> 0 | I39: =+IFERROR(I7/I$11,0) -> 0 | J39: =+IFERROR(J7/J$11,0) -> 0 | K39: =+IFERROR(K7/K$11,0) -> 0.24324324 | ... M39: =+IFERROR(M7/M$11,0) -> 0
B40: Omega | C40: Aguirre Luco | D40: =+IFERROR(D8/D$11,0) -> 0 | E40: =+IFERROR(E8/E$11,0) -> 0.10344828 | F40: =+IFERROR(F8/F$11,0) -> 0.47142857 | G40: =+IFERROR(G8/G$11,0) -> 0 | H40: =+IFERROR(H8/H$11,0) -> 0 | I40: =+IFERROR(I8/I$11,0) -> 0.37313433 | J40: =+IFERROR(J8/J$11,0) -> 0 | K40: =+IFERROR(K8/K$11,0) -> 0 | ... M40: =+IFERROR(M8/M$11,0) -> 0
C41: Pie Andino | D41: =+IFERROR(D9/D$11,0) -> 0.23809524 | E41: =+IFERROR(E9/E$11,0) -> 0.25862069 | F41: =+IFERROR(F9/F$11,0) -> 0.52857143 | G41: =+IFERROR(G9/G$11,0) -> 0 | H41: =+IFERROR(H9/H$11,0) -> 0.020833333 | I41: =+IFERROR(I9/I$11,0) -> 0 | J41: =+IFERROR(J9/J$11,0) -> 0 | K41: =+IFERROR(K9/K$11,0) -> 0 | ... M41: =+IFERROR(M9/M$11,0) -> 0
C42: Juanita | D42: =+IFERROR(D10/D$11,0) -> 0.31428571 | E42: =+IFERROR(E10/E$11,0) -> 0 | F42: =+IFERROR(F10/F$11,0) -> 0 | G42: =+IFERROR(G10/G$11,0) -> 0 | H42: =+IFERROR(H10/H$11,0) -> 0.625 | I42: =+IFERROR(I10/I$11,0) -> 0 | J42: =+IFERROR(J10/J$11,0) -> 0 | K42: =+IFERROR(K10/K$11,0) -> 0 | ... M42: =+IFERROR(M10/M$11,0) -> 1
B43: Total | D43: =SUM(D36:D42) -> 1 | E43: =SUM(E36:E42) -> 1 | F43: =SUM(F36:F42) -> 1 | G43: =SUM(G36:G42) -> 1 | H43: =SUM(H36:H42) -> 1 | I43: =SUM(I36:I42) -> 1 | J43: =SUM(J36:J42) -> 1 | K43: =SUM(K36:K42) -> 1 | ... M43: =SUM(M36:M42) -> 1
B47: Empresa | C47: Terminal | D47: Foton | E47: Volvo | H47: Mercedes Benz | K47: Scania | M47: Yutong
D48: BE | E48: A2 | F48: B2 | G48: C2 | H48: B2 | I48: BPAL | J48: C2 | K48: B2 | L48: BPAL | M48: BE
B49: Alfa | C49: El Retiro | D49: =+IFERROR(D4/$N4,0) -> 0 | E49: =+IFERROR(E4/$N4,0) -> 0.18965517 | F49: =+IFERROR(F4/$N4,0) -> 0 | G49: =+IFERROR(G4/$N4,0) -> 0.32758621 | H49: =+IFERROR(H4/$N4,0) -> 0 | I49: =+IFERROR(I4/$N4,0) -> 0 | J49: =+IFERROR(J4/$N4,0) -> 0 | K49: =+IFERROR(K4/$N4,0) -> 0.48275862 | ... M49: =+IFERROR(M4/$N4,0) -> 0 | N49: =+SUM(D49:M49) -> 1
C50: Condell | D50: =+IFERROR(D5/$N5,0) -> 0.5859375 | E50: =+IFERROR(E5/$N5,0) -> 0.078125 | F50: =+IFERROR(F5/$N5,0) -> 0 | G50: =+IFERROR(G5/$N5,0) -> 0.0546875 | H50: =+IFERROR(H5/$N5,0) -> 0.09375 | I50: =+IFERROR(I5/$N5,0) -> 0 | J50: =+IFERROR(J5/$N5,0) -> 0.1875 | K50: =+IFERROR(K5/$N5,0) -> 0 | ... M50: =+IFERROR(M5/$N5,0) -> 0 | N50: =+SUM(D50:M50) -> 1
C51: Santa Marta | D51: =+IFERROR(D6/$N6,0) -> 0.44295302 | E51: =+IFERROR(E6/$N6,0) -> 0.10738255 | F51: =+IFERROR(F6/$N6,0) -> 0 | G51: =+IFERROR(G6/$N6,0) -> 0 | H51: =+IFERROR(H6/$N6,0) -> 0.14765101 | I51: =+IFERROR(I6/$N6,0) -> 0.28187919 | J51: =+IFERROR(J6/$N6,0) -> 0 | K51: =+IFERROR(K6/$N6,0) -> 0 | ... M51: =+IFERROR(M6/$N6,0) -> 0 | N51: =+SUM(D51:M51) -> 1
C52: Santa Margarita | D52: =+IFERROR(D7/$N7,0) -> 0 | E52: =+IFERROR(E7/$N7,0) -> 0 | F52: =+IFERROR(F7/$N7,0) -> 0 | G52: =+IFERROR(G7/$N7,0) -> 0.67857143 | H52: =+IFERROR(H7/$N7,0) -> 0 | I52: =+IFERROR(I7/$N7,0) -> 0 | J52: =+IFERROR(J7/$N7,0) -> 0 | K52: =+IFERROR(K7/$N7,0) -> 0.32142857 | ... M52: =+IFERROR(M7/$N7,0) -> 0 | N52: =+SUM(D52:M52) -> 1
B53: Omega | C53: Aguirre Luco | D53: =+IFERROR(D8/$N8,0) -> 0 | E53: =+IFERROR(E8/$N8,0) -> 0.09375 | F53: =+IFERROR(F8/$N8,0) -> 0.515625 | G53: =+IFERROR(G8/$N8,0) -> 0 | H53: =+IFERROR(H8/$N8,0) -> 0 | I53: =+IFERROR(I8/$N8,0) -> 0.390625 | J53: =+IFERROR(J8/$N8,0) -> 0 | K53: =+IFERROR(K8/$N8,0) -> 0 | ... M53: =+IFERROR(M8/$N8,0) -> 0 | N53: =+SUM(D53:M53) -> 1
C54: Pie Andino | D54: =+IFERROR(D9/$N9,0) -> 0.58139535 | E54: =+IFERROR(E9/$N9,0) -> 0.11627907 | F54: =+IFERROR(F9/$N9,0) -> 0.28682171 | G54: =+IFERROR(G9/$N9,0) -> 0 | H54: =+IFERROR(H9/$N9,0) -> 0.015503876 | I54: =+IFERROR(I9/$N9,0) -> 0 | J54: =+IFERROR(J9/$N9,0) -> 0 | K54: =+IFERROR(K9/$N9,0) -> 0 | ... M54: =+IFERROR(M9/$N9,0) -> 0 | N54: =+SUM(D54:M54) -> 1
...

Sheet Hoja3
B2: Empresa | C2: Terminal | D2: Foton | E2: Volvo | H2: Mercedes Benz | K2: Scania | M2: Yutong | N2: Total
D3: BE | E3: A2 | F3: B2 | G3: C2 | H3: B2 | I3: BPAL | J3: C2 | K3: B2 | L3: BPAL | M3: BE
B4: Alfa | C4: El Retiro | D4: 0 | E4: 11 | F4: 0 | G4: 19 | H4: 0 | I4: 0 | J4: 0 | K4: 33 | L4: 0 | M4: 0 | N4: =SUM(D4:M4) -> 63
C5: Condell | D5: 75 | E5: 10 | F5: 0 | G5: 7 | H5: 12 | I5: 0 | J5: 24 | K5: 0 | L5: 0 | M5: 0 | N5: =SUM(D5:M5) -> 128
C6: Santa Marta | D6: 66 | E6: 16 | F6: 0 | G6: 0 | H6: 18 | I6: 39 | J6: 0 | K6: 0 | L6: 3 | M6: 0 | N6: =SUM(D6:M6) -> 142
C7: Santa Margarita | D7: 0 | E7: 0 | F7: 0 | G7: 19 | H7: 4 | I7: 0 | J7: 0 | K7: 5 | L7: 0 | M7: 0 | N7: =SUM(D7:M7) -> 28
B8: Omega | C8: Aguirre Luco | D8: 0 | E8: 6 | F8: 36 | G8: 0 | H8: 0 | I8: 20 | J8: 0 | K8: 0 | L8: 0 | M8: 0 | N8: =SUM(D8:M8) -> 62
C9: Pie Andino | D9: 93 | E9: 15 | F9: 34 | G9: 0 | H9: 26 | I9: 7 | J9: 0 | K9: 0 | L9: 0 | M9: 0 | N9: =SUM(D9:M9) -> 175
C10: Juanita | D10: 82 | E10: 0 | F10: 0 | G10: 0 | H10: 36 | I10: 0 | J10: 0 | K10: 0 | L10: 0 | M10: 25 | N10: =SUM(D10:M10) -> 143
B11: Total | D11: 316 | E11: 58 | F11: 70 | G11: 45 | H11: 96 | I11: 66 | J11: 24 | K11: 38 | L11: 3 | M11: 25 | N11: =SUM(N4:N10) -> 741

Sheet Hoja2
A1: EMPRESA | B1: PATENTE | C1: INTERNO | D1: TIPO DE BUS | E1: MARCA | F1: TERMINAL | G1: Where is it?
A2: US2 | B2: LBTT14 | C2: 6055 | D2: B2D | E2: Mercedes | F2: Juanita | H2: =VLOOKUP(B2,DitrbFlota[PLACA],1,0) -> LBTT14
A3: US2 | B3: LBTT15 | C3: 6056 | D3: B2D | E3: Mercedes | F3: Juanita | H3: =VLOOKUP(B3,DitrbFlota[PLACA],1,0) -> LBTT15
A4: US2 | B4: LBTT16 | C4: 6057 | D4: B2D | E4: Mercedes | F4: Juanita | H4: =VLOOKUP(B4,DitrbFlota[PLACA],1,0) -> LBTT16
A5: US2 | B5: LBTT17 | C5: 6058 | D5: B2D | E5: Mercedes | F5: Juanita | H5: =VLOOKUP(B5,DitrbFlota[PLACA],1,0) -> LBTT17
A6: US2 | B6: LBTT18 | C6: 6059 | D6: B2D | E6: Mercedes | F6: Juanita | H6: =VLOOKUP(B6,DitrbFlota[PLACA],1,0) -> LBTT18
A7: US2 | B7: LBTS80 | C7: 6032 | D7: B2D | E7: Mercedes | F7: Juanita | G7: Reemplazo al LBTT19 | H7: =VLOOKUP(B7,DitrbFlota[PLACA],1,0) -> LBTS80
A8: US2 | B8: LBTT20 | C8: 6061 | D8: B2D | E8: Mercedes | F8: Juanita | H8: =VLOOKUP(B8,DitrbFlota[PLACA],1,0) -> LBTT20
A9: US2 | B9: LBTT21 | C9: 6062 | D9: B2D | E9: Mercedes | F9: Juanita | H9: =VLOOKUP(B9,DitrbFlota[PLACA],1,0) -> LBTT21
A10: US2 | B10: LBTT22 | C10: 6063 | D10: B2D | E10: Mercedes | F10: Juanita | H10: =VLOOKUP(B10,DitrbFlota[PLACA],1,0) -> LBTT22
A11: US2 | B11: LBTT23 | C11: 6064 | D11: B2D | E11: Mercedes | F11: Juanita | H11: =VLOOKUP(B11,DitrbFlota[PLACA],1,0) -> LBTT23
A12: US2 | B12: LBTT24 | C12: 6065 | D12: B2D | E12: Mercedes | F12: Juanita | H12: =VLOOKUP(B12,DitrbFlota[PLACA],1,0) -> LBTT24
A13: US2 | B13: LBTT25 | C13: 6066 | D13: B2D | E13: Mercedes | F13: Juanita | H13: =VLOOKUP(B13,DitrbFlota[PLACA],1,0) -> LBTT25
A14: US2 | B14: LCPG31 | C14: 6067 | D14: B2D | E14: Mercedes | F14: Juanita | H14: =VLOOKUP(B14,DitrbFlota[PLACA],1,0) -> LCPG31
A15: US2 | B15: LCPG32 | C15: 6068 | D15: B2D | E15: Mercedes | F15: Juanita | H15: =VLOOKUP(B15,DitrbFlota[PLACA],1,0) -> LCPG32
A16: US2 | B16: LCPG33 | C16: 6069 | D16: B2D | E16: Mercedes | F16: Juanita | H16: =VLOOKUP(B16,DitrbFlota[PLACA],1,0) -> LCPG33
A17: US2 | B17: LCPG34 | C17: 6070 | D17: B2D | E17: Mercedes | F17: Juanita | H17: =VLOOKUP(B17,DitrbFlota[PLACA],1,0) -> LCPG34
A18: US2 | B18: LCPG34 | C18: 6070 | D18: B2D | E18: Mercedes | F18: Juanita | G18: STP (SINIESTRADO) | H18: =VLOOKUP(B18,DitrbFlota[PLACA],1,0) -> LCPG34
A19: US2 | B19: LCPG36 | C19: 6072 | D19: B2D | E19: Mercedes | F19: Juanita | H19: =VLOOKUP(B19,DitrbFlota[PLACA],1,0) -> LCPG36
A20: US2 | B20: LCPG37 | C20: 6073 | D20: B2D | E20: Mercedes | F20: Juanita | H20: =VLOOKUP(B20,DitrbFlota[PLACA],1,0) -> LCPG37
A21: US2 | B21: LCPG38 | C21: 6074 | D21: B2D | E21: Mercedes | F21: Juanita | H21: =VLOOKUP(B21,DitrbFlota[PLACA],1,0) -> LCPG38
A22: US2 | B22: LCPG39 | C22: 6075 | D22: B2D | E22: Mercedes | F22: Juanita | H22: =VLOOKUP(B22,DitrbFlota[PLACA],1,0) -> LCPG39
A23: US2 | B23: LCPG40 | C23: 6076 | D23: B2D | E23: Mercedes | F23: Juanita | H23: =VLOOKUP(B23,DitrbFlota[PLACA],1,0) -> LCPG40
A24: US2 | B24: LCPG41 | C24: 6077 | D24: B2D | E24: Mercedes | F24: Juanita | H24: =VLOOKUP(B24,DitrbFlota[PLACA],1,0) -> LCPG41
A25: US2 | B25: LCPG42 | C25: 6078 | D25: B2D | E25: Mercedes | F25: Juanita | H25: =VLOOKUP(B25,DitrbFlota[PLACA],1,0) -> LCPG42
A26: US2 | B26: LCPG43 | C26: 6079 | D26: B2D | E26: Mercedes | F26: Juanita | H26: =VLOOKUP(B26,DitrbFlota[PLACA],1,0) -> LCPG43
A27: US2 | B27: LCPG44 | C27: 6080 | D27: B2D | E27: Mercedes | F27: Juanita | H27: =VLOOKUP(B27,DitrbFlota[PLACA],1,0) -> LCPG44
A28: US2 | B28: LCPG45 | C28: 6081 | D28: B2D | E28: Mercedes | F28: Juanita | H28: =VLOOKUP(B28,DitrbFlota[PLACA],1,0) -> LCPG45
A29: US2 | B29: LCPG46 | C29: 6082 | D29: B2D | E29: Mercedes | F29: Juanita | H29: =VLOOKUP(B29,DitrbFlota[PLACA],1,0) -> LCPG46
A30: US2 | B30: LCPG47 | C30: 6083 | D30: B2D | E30: Mercedes | F30: Juanita | H30: =VLOOKUP(B30,DitrbFlota[PLACA],1,0) -> LCPG47
... A126: US2 | B126: STHD50 | C126: 7184 | D126: BE | E126: Foton | F126: Juanita | H126: =VLOOKUP(B126,DitrbFlota[PLACA],1,0) -> STHD50
A127: US2 | B127: STHD26 | C127: 7185 | D127: BE | E127: Foton | F127: Juanita | G127: BUS DE REEMPLAZO | H127: =VLOOKUP(B127,DitrbFlota[PLACA],1,0) -> STHD26
A128: US2 | B128: STHF36 | C128: 7186 | D128: BE | E128: Foton | F128: Juanita | H128: =VLOOKUP(B128,DitrbFlota[PLACA],1,0) -> STHF36
A129: US2 | B129: STHF56 | C129: 7187 | D129: BE | E129: Foton | F129: Juanita | H129: =VLOOKUP(B129,DitrbFlota[PLACA],1,0) -> STHF56
A130: US2 | B130: STHF57 | C130: 7188 | D130: BE | E130: Foton | F130: Juanita | H130: =VLOOKUP(B130,DitrbFlota[PLACA],1,0) -> STHF57
A131: US2 | B131: STHF67 | C131: 7189 | D131: BE | E131: Foton | F131: Juanita | H131: =VLOOKUP(B131,DitrbFlota[PLACA],1,0) -> STHF67
A132: US2 | B132: STHF69 | C132: 7190 | D132: BE | E132: Foton | F132: Juanita | H132: =VLOOKUP(B132,DitrbFlota[PLACA],1,0) -> STHF69

Sheet Hoja1
A3: Etiquetas de fila | B3: Cuenta de TIPO BUS
A4: FOTON | B4: 315
A5: MERCEDES BENZ | B5: 187 | C5: =+B5 -> 187 | D5: =+C5/$C$8 -> 0.4675
A6: SCANIA | B6: 40 | C6: =+B6 -> 40 | D6: =+C6/$C$8 -> 0.1
A7: VOLVO | B7: 173 | C7: =+B7 -> 173 | D7: =+C7/$C$8 -> 0.4325
A8: YUTONG | B8: 25 | C8: =+SUM(C5:C7) -> 400
A9: Total general | B9: 740

Sheet Mov El Retiro
A1: PLACA | B1: INTERNO | C1: TIPO BUS | D1: TIPO FLOTA | E1: MARCA CHASIS | F1: Estado | G1: TERMINAL Actual | H1: Terminal Destino | I1: Movimiento | J1: Servicio | K1: Terminal | L1: terminal alicia | O1: Empresa | P1: Terminal | Q1: Foton | R1: Volvo | U1: Mercedes Benz | X1: Scania | Y1: Total
